2021-09-27 22:50:58,149 INFO    Thread-13 :280680 [wandb_setup.py:_flush():69] setting env: {'root_dir': '/grid/koo/home/toneyan/profile/QuantPred', 'entity': 'toneyan', 'project': 'BASENJI_TRAINSET_THRESHOLD', 'run_id': '9rw4s42z', 'sweep_param_path': '/grid/koo/home/toneyan/profile/QuantPred/wandb/sweep-vsb41k4w/config-9rw4s42z.yaml', 'sweep_id': 'vsb41k4w'}
2021-09-27 22:50:58,149 INFO    Thread-13 :280680 [wandb_setup.py:_flush():69] setting login settings: {}
2021-09-27 22:50:58,149 INFO    Thread-13 :280680 [wandb_init.py:_log_setup():337] Logging user logs to /grid/koo/home/toneyan/profile/QuantPred/wandb/run-20210927_225058-9rw4s42z/logs/debug.log
2021-09-27 22:50:58,149 INFO    Thread-13 :280680 [wandb_init.py:_log_setup():338] Logging internal logs to /grid/koo/home/toneyan/profile/QuantPred/wandb/run-20210927_225058-9rw4s42z/logs/debug-internal.log
2021-09-27 22:50:58,149 INFO    Thread-13 :280680 [wandb_init.py:init():370] calling init triggers
2021-09-27 22:50:58,149 INFO    Thread-13 :280680 [wandb_init.py:init():377] wandb.init called with sweep_config: {'bin_size': 1, 'data_dir': 'datasets/train_thresholds/threshold_6/i_3072_w_1', 'l_rate': 0.001, 'loss_fn': 'poisson', 'model_fn': 'basenji_w1_b64', 'num_epochs': 100, 'window_size': 2048}
config: {}
2021-09-27 22:50:58,150 INFO    Thread-13 :280680 [wandb_init.py:init():419] starting backend
2021-09-27 22:50:58,150 INFO    Thread-13 :280680 [backend.py:_multiprocessing_setup():72] multiprocessing start_methods=fork,spawn,forkserver, using: spawn
2021-09-27 22:50:58,152 INFO    Thread-13 :280680 [backend.py:ensure_launched():135] starting backend process...
2021-09-27 22:50:58,173 INFO    Thread-13 :280680 [backend.py:ensure_launched():140] started backend process with pid: 685491
2021-09-27 22:50:58,175 INFO    Thread-13 :280680 [wandb_init.py:init():424] backend started and connected
2021-09-27 22:50:58,177 INFO    Thread-13 :280680 [wandb_run.py:_config_callback():872] config_cb None None {'bin_size': 1, 'data_dir': 'datasets/train_thresholds/threshold_6/i_3072_w_1', 'l_rate': 0.001, 'loss_fn': 'poisson', 'model_fn': 'basenji_w1_b64', 'num_epochs': 100, 'window_size': 2048}
2021-09-27 22:50:58,177 INFO    Thread-13 :280680 [wandb_init.py:init():472] updated telemetry
2021-09-27 22:50:58,178 INFO    Thread-13 :280680 [wandb_init.py:init():491] communicating current version
2021-09-27 22:50:58,714 INFO    Thread-13 :280680 [wandb_init.py:init():496] got version response upgrade_message: "wandb version 0.12.2 is available!  To upgrade, please run:\n $ pip install wandb --upgrade"

2021-09-27 22:50:58,714 INFO    Thread-13 :280680 [wandb_init.py:init():504] communicating run to backend with 30 second timeout
2021-09-27 22:50:58,795 INFO    Thread-13 :280680 [wandb_init.py:init():529] starting run threads in backend
2021-09-27 22:50:59,783 INFO    Thread-13 :280680 [wandb_run.py:_console_start():1623] atexit reg
2021-09-27 22:50:59,784 INFO    Thread-13 :280680 [wandb_run.py:_redirect():1497] redirect: SettingsConsole.REDIRECT
2021-09-27 22:50:59,784 INFO    Thread-13 :280680 [wandb_run.py:_redirect():1502] Redirecting console.
2021-09-27 22:50:59,784 ERROR   Thread-13 :280680 [wandb_run.py:_redirect():1561] Failed to redirect.
Traceback (most recent call last):
  File "/usr/local/lib/python3.6/dist-packages/wandb/sdk/wandb_run.py", line 1554, in _redirect
    out_redir.install()
  File "/usr/local/lib/python3.6/dist-packages/wandb/sdk/lib/redirect.py", line 709, in install
    _WSCH.add_fd(self._pipe_read_fd)
  File "/usr/local/lib/python3.6/dist-packages/wandb/sdk/lib/redirect.py", line 659, in add_fd
    self._register()
  File "/usr/local/lib/python3.6/dist-packages/wandb/sdk/lib/redirect.py", line 644, in _register
    old_handler = signal.signal(signal.SIGWINCH, lambda *_: None)
  File "/usr/lib/python3.6/signal.py", line 47, in signal
    handler = _signal.signal(_enum_to_int(signalnum), _enum_to_int(handler))
ValueError: signal only works in main thread
2021-09-27 22:50:59,785 INFO    Thread-13 :280680 [wandb_init.py:init():554] run started, returning control to user process
2021-09-27 23:54:07,411 ERROR   Thread-2  :280680 [internal_api.py:execute():130] 502 response executing GraphQL.
2021-09-27 23:54:07,468 ERROR   Thread-2  :280680 [internal_api.py:execute():131] 
<html><head>
<meta http-equiv="content-type" content="text/html;charset=utf-8">
<title>502 Server Error</title>
</head>
<body text=#000000 bgcolor=#ffffff>
<h1>Error: Server Error</h1>
<h2>The server encountered a temporary error and could not complete your request.<p>Please try again in 30 seconds.</h2>
<h2></h2>
</body></html>

2021-09-28 03:54:39,585 ERROR   Thread-2  :280680 [retry.py:__call__():126] Retry attempt failed:
Traceback (most recent call last):
  File "/usr/local/lib/python3.6/dist-packages/urllib3/connection.py", line 170, in _new_conn
    (self._dns_host, self.port), self.timeout, **extra_kw
  File "/usr/local/lib/python3.6/dist-packages/urllib3/util/connection.py", line 73, in create_connection
    for res in socket.getaddrinfo(host, port, family, socket.SOCK_STREAM):
  File "/usr/lib/python3.6/socket.py", line 745, in getaddrinfo
    for res in _socket.getaddrinfo(host, port, family, type, proto, flags):
socket.gaierror: [Errno -5] No address associated with hostname

During handling of the above exception, another exception occurred:

Traceback (most recent call last):
  File "/usr/local/lib/python3.6/dist-packages/urllib3/connectionpool.py", line 706, in urlopen
    chunked=chunked,
  File "/usr/local/lib/python3.6/dist-packages/urllib3/connectionpool.py", line 382, in _make_request
    self._validate_conn(conn)
  File "/usr/local/lib/python3.6/dist-packages/urllib3/connectionpool.py", line 1010, in _validate_conn
    conn.connect()
  File "/usr/local/lib/python3.6/dist-packages/urllib3/connection.py", line 353, in connect
    conn = self._new_conn()
  File "/usr/local/lib/python3.6/dist-packages/urllib3/connection.py", line 182, in _new_conn
    self, "Failed to establish a new connection: %s" % e
urllib3.exceptions.NewConnectionError: <urllib3.connection.HTTPSConnection object at 0x1554d7d9fb70>: Failed to establish a new connection: [Errno -5] No address associated with hostname

During handling of the above exception, another exception occurred:

Traceback (most recent call last):
  File "/usr/local/lib/python3.6/dist-packages/requests/adapters.py", line 449, in send
    timeout=timeout
  File "/usr/local/lib/python3.6/dist-packages/urllib3/connectionpool.py", line 756, in urlopen
    method, url, error=e, _pool=self, _stacktrace=sys.exc_info()[2]
  File "/usr/local/lib/python3.6/dist-packages/urllib3/util/retry.py", line 573, in increment
    raise MaxRetryError(_pool, url, error or ResponseError(cause))
urllib3.exceptions.MaxRetryError: HTTPSConnectionPool(host='api.wandb.ai', port=443): Max retries exceeded with url: /graphql (Caused by NewConnectionError('<urllib3.connection.HTTPSConnection object at 0x1554d7d9fb70>: Failed to establish a new connection: [Errno -5] No address associated with hostname',))

During handling of the above exception, another exception occurred:

Traceback (most recent call last):
  File "/usr/local/lib/python3.6/dist-packages/wandb/sdk/lib/retry.py", line 102, in __call__
    result = self._call_fn(*args, **kwargs)
  File "/usr/local/lib/python3.6/dist-packages/wandb/sdk/internal/internal_api.py", line 127, in execute
    return self.client.execute(*args, **kwargs)
  File "/usr/local/lib/python3.6/dist-packages/wandb/vendor/gql-0.2.0/gql/client.py", line 52, in execute
    result = self._get_result(document, *args, **kwargs)
  File "/usr/local/lib/python3.6/dist-packages/wandb/vendor/gql-0.2.0/gql/client.py", line 60, in _get_result
    return self.transport.execute(document, *args, **kwargs)
  File "/usr/local/lib/python3.6/dist-packages/wandb/vendor/gql-0.2.0/gql/transport/requests.py", line 38, in execute
    request = requests.post(self.url, **post_args)
  File "/usr/local/lib/python3.6/dist-packages/requests/api.py", line 119, in post
    return request('post', url, data=data, json=json, **kwargs)
  File "/usr/local/lib/python3.6/dist-packages/requests/api.py", line 61, in request
    return session.request(method=method, url=url, **kwargs)
  File "/usr/local/lib/python3.6/dist-packages/requests/sessions.py", line 542, in request
    resp = self.send(prep, **send_kwargs)
  File "/usr/local/lib/python3.6/dist-packages/requests/sessions.py", line 655, in send
    r = adapter.send(request, **kwargs)
  File "/usr/local/lib/python3.6/dist-packages/requests/adapters.py", line 516, in send
    raise ConnectionError(e, request=request)
requests.exceptions.ConnectionError: HTTPSConnectionPool(host='api.wandb.ai', port=443): Max retries exceeded with url: /graphql (Caused by NewConnectionError('<urllib3.connection.HTTPSConnection object at 0x1554d7d9fb70>: Failed to establish a new connection: [Errno -5] No address associated with hostname',))
2021-09-28 04:20:24,405 INFO    Thread-13 :280680 [wandb_run.py:finish():1293] finishing run toneyan/BASENJI_TRAINSET_THRESHOLD/9rw4s42z
