2021-09-14 05:58:47,943 INFO    Thread-23 :988785 [wandb_setup.py:_flush():69] setting env: {'root_dir': '/grid/koo/home/toneyan/profile/QuantPred', 'entity': 'toneyan', 'project': 'FINETUNE_BASENJI_128_POISSON_AUGM', 'run_id': '74zvf87w', 'sweep_param_path': '/grid/koo/home/toneyan/profile/QuantPred/wandb/sweep-1wx7gfow/config-74zvf87w.yaml', 'sweep_id': '1wx7gfow'}
2021-09-14 05:58:47,943 INFO    Thread-23 :988785 [wandb_setup.py:_flush():69] setting login settings: {}
2021-09-14 05:58:47,943 INFO    Thread-23 :988785 [wandb_init.py:_log_setup():337] Logging user logs to /grid/koo/home/toneyan/profile/QuantPred/wandb/run-20210914_055847-74zvf87w/logs/debug.log
2021-09-14 05:58:47,943 INFO    Thread-23 :988785 [wandb_init.py:_log_setup():338] Logging internal logs to /grid/koo/home/toneyan/profile/QuantPred/wandb/run-20210914_055847-74zvf87w/logs/debug-internal.log
2021-09-14 05:58:47,944 INFO    Thread-23 :988785 [wandb_init.py:init():370] calling init triggers
2021-09-14 05:58:47,944 INFO    Thread-23 :988785 [wandb_init.py:init():377] wandb.init called with sweep_config: {'add_dropout': False, 'bin_size': 128, 'data_dir': 'datasets/complete/random_chop/i_3072_w_1/', 'epochN': 30, 'filtN_1': 64, 'filtN_2': 256, 'filtN_4': 64, 'filtN_5': 256, 'l_rate': 0.001, 'loss_fn': 'poisson', 'model_fn': 'basenjimod', 'window_size': 2048}
config: {}
2021-09-14 05:58:47,944 INFO    Thread-23 :988785 [wandb_init.py:init():419] starting backend
2021-09-14 05:58:47,944 INFO    Thread-23 :988785 [backend.py:_multiprocessing_setup():72] multiprocessing start_methods=fork,spawn,forkserver, using: spawn
2021-09-14 05:58:47,947 INFO    Thread-23 :988785 [backend.py:ensure_launched():135] starting backend process...
2021-09-14 05:58:47,961 INFO    Thread-23 :988785 [backend.py:ensure_launched():140] started backend process with pid: 1264168
2021-09-14 05:58:47,963 INFO    Thread-23 :988785 [wandb_init.py:init():424] backend started and connected
2021-09-14 05:58:47,965 INFO    Thread-23 :988785 [wandb_run.py:_config_callback():872] config_cb None None {'add_dropout': False, 'bin_size': 128, 'data_dir': 'datasets/complete/random_chop/i_3072_w_1/', 'epochN': 30, 'filtN_1': 64, 'filtN_2': 256, 'filtN_4': 64, 'filtN_5': 256, 'l_rate': 0.001, 'loss_fn': 'poisson', 'model_fn': 'basenjimod', 'window_size': 2048}
2021-09-14 05:58:47,966 INFO    Thread-23 :988785 [wandb_init.py:init():472] updated telemetry
2021-09-14 05:58:47,966 INFO    Thread-23 :988785 [wandb_init.py:init():491] communicating current version
2021-09-14 05:58:48,541 INFO    Thread-23 :988785 [wandb_init.py:init():496] got version response upgrade_message: "wandb version 0.12.1 is available!  To upgrade, please run:\n $ pip install wandb --upgrade"

2021-09-14 05:58:48,541 INFO    Thread-23 :988785 [wandb_init.py:init():504] communicating run to backend with 30 second timeout
2021-09-14 05:58:48,623 INFO    Thread-23 :988785 [wandb_init.py:init():529] starting run threads in backend
2021-09-14 05:58:49,788 INFO    Thread-23 :988785 [wandb_run.py:_console_start():1623] atexit reg
2021-09-14 05:58:49,789 INFO    Thread-23 :988785 [wandb_run.py:_redirect():1497] redirect: SettingsConsole.REDIRECT
2021-09-14 05:58:49,789 INFO    Thread-23 :988785 [wandb_run.py:_redirect():1502] Redirecting console.
2021-09-14 05:58:49,790 ERROR   Thread-23 :988785 [wandb_run.py:_redirect():1561] Failed to redirect.
Traceback (most recent call last):
  File "/usr/local/lib/python3.6/dist-packages/wandb/sdk/wandb_run.py", line 1554, in _redirect
    out_redir.install()
  File "/usr/local/lib/python3.6/dist-packages/wandb/sdk/lib/redirect.py", line 709, in install
    _WSCH.add_fd(self._pipe_read_fd)
  File "/usr/local/lib/python3.6/dist-packages/wandb/sdk/lib/redirect.py", line 659, in add_fd
    self._register()
  File "/usr/local/lib/python3.6/dist-packages/wandb/sdk/lib/redirect.py", line 644, in _register
    old_handler = signal.signal(signal.SIGWINCH, lambda *_: None)
  File "/usr/lib/python3.6/signal.py", line 47, in signal
    handler = _signal.signal(_enum_to_int(signalnum), _enum_to_int(handler))
ValueError: signal only works in main thread
2021-09-14 05:58:49,791 INFO    Thread-23 :988785 [wandb_init.py:init():554] run started, returning control to user process
2021-09-14 05:58:53,970 ERROR   Thread-2  :988785 [internal_api.py:execute():130] 429 response executing GraphQL.
2021-09-14 05:58:53,970 ERROR   Thread-2  :988785 [internal_api.py:execute():131] {"error":"rate limit exceeded"}

2021-09-14 05:58:55,224 ERROR   Thread-2  :988785 [internal_api.py:execute():130] 429 response executing GraphQL.
2021-09-14 05:58:55,224 ERROR   Thread-2  :988785 [internal_api.py:execute():131] {"error":"rate limit exceeded"}

2021-09-14 05:58:57,678 ERROR   Thread-2  :988785 [internal_api.py:execute():130] 429 response executing GraphQL.
2021-09-14 05:58:57,678 ERROR   Thread-2  :988785 [internal_api.py:execute():131] {"error":"rate limit exceeded"}

2021-09-14 05:58:57,678 ERROR   Thread-2  :988785 [retry.py:__call__():126] Retry attempt failed:
Traceback (most recent call last):
  File "/usr/local/lib/python3.6/dist-packages/wandb/sdk/lib/retry.py", line 102, in __call__
    result = self._call_fn(*args, **kwargs)
  File "/usr/local/lib/python3.6/dist-packages/wandb/sdk/internal/internal_api.py", line 133, in execute
    six.reraise(*sys.exc_info())
  File "/usr/local/lib/python3.6/dist-packages/six.py", line 719, in reraise
    raise value
  File "/usr/local/lib/python3.6/dist-packages/wandb/sdk/internal/internal_api.py", line 127, in execute
    return self.client.execute(*args, **kwargs)
  File "/usr/local/lib/python3.6/dist-packages/wandb/vendor/gql-0.2.0/gql/client.py", line 52, in execute
    result = self._get_result(document, *args, **kwargs)
  File "/usr/local/lib/python3.6/dist-packages/wandb/vendor/gql-0.2.0/gql/client.py", line 60, in _get_result
    return self.transport.execute(document, *args, **kwargs)
  File "/usr/local/lib/python3.6/dist-packages/wandb/vendor/gql-0.2.0/gql/transport/requests.py", line 39, in execute
    request.raise_for_status()
  File "/usr/local/lib/python3.6/dist-packages/requests/models.py", line 943, in raise_for_status
    raise HTTPError(http_error_msg, response=self)
requests.exceptions.HTTPError: 429 Client Error: Too Many Requests for url: https://api.wandb.ai/graphql
2021-09-14 05:59:04,910 ERROR   Thread-2  :988785 [internal_api.py:execute():130] 429 response executing GraphQL.
2021-09-14 05:59:04,911 ERROR   Thread-2  :988785 [internal_api.py:execute():131] {"error":"rate limit exceeded"}

2021-09-14 05:59:06,087 ERROR   Thread-2  :988785 [internal_api.py:execute():130] 429 response executing GraphQL.
2021-09-14 05:59:06,088 ERROR   Thread-2  :988785 [internal_api.py:execute():131] {"error":"rate limit exceeded"}

2021-09-14 05:59:08,537 ERROR   Thread-2  :988785 [internal_api.py:execute():130] 429 response executing GraphQL.
2021-09-14 05:59:08,537 ERROR   Thread-2  :988785 [internal_api.py:execute():131] {"error":"rate limit exceeded"}

2021-09-14 05:59:08,537 ERROR   Thread-2  :988785 [retry.py:__call__():126] Retry attempt failed:
Traceback (most recent call last):
  File "/usr/local/lib/python3.6/dist-packages/wandb/sdk/lib/retry.py", line 102, in __call__
    result = self._call_fn(*args, **kwargs)
  File "/usr/local/lib/python3.6/dist-packages/wandb/sdk/internal/internal_api.py", line 133, in execute
    six.reraise(*sys.exc_info())
  File "/usr/local/lib/python3.6/dist-packages/six.py", line 719, in reraise
    raise value
  File "/usr/local/lib/python3.6/dist-packages/wandb/sdk/internal/internal_api.py", line 127, in execute
    return self.client.execute(*args, **kwargs)
  File "/usr/local/lib/python3.6/dist-packages/wandb/vendor/gql-0.2.0/gql/client.py", line 52, in execute
    result = self._get_result(document, *args, **kwargs)
  File "/usr/local/lib/python3.6/dist-packages/wandb/vendor/gql-0.2.0/gql/client.py", line 60, in _get_result
    return self.transport.execute(document, *args, **kwargs)
  File "/usr/local/lib/python3.6/dist-packages/wandb/vendor/gql-0.2.0/gql/transport/requests.py", line 39, in execute
    request.raise_for_status()
  File "/usr/local/lib/python3.6/dist-packages/requests/models.py", line 943, in raise_for_status
    raise HTTPError(http_error_msg, response=self)
requests.exceptions.HTTPError: 429 Client Error: Too Many Requests for url: https://api.wandb.ai/graphql
2021-09-14 05:59:13,189 ERROR   Thread-2  :988785 [internal_api.py:execute():130] 429 response executing GraphQL.
2021-09-14 05:59:13,189 ERROR   Thread-2  :988785 [internal_api.py:execute():131] {"error":"rate limit exceeded"}

2021-09-14 05:59:22,815 INFO    Thread-23 :988785 [wandb_run.py:finish():1293] finishing run toneyan/FINETUNE_BASENJI_128_POISSON_AUGM/74zvf87w
