2021-10-13 13:30:35,920 INFO    Thread-3  :1615915 [wandb_setup.py:_flush():69] setting env: {'root_dir': '/grid/koo/home/ztang/QuantPred', 'sweep_id': 'lksquwjl', 'entity': 'ambert', 'project': 'center_bpnet_bin_loss', 'run_id': 'mybo8rqi', 'sweep_param_path': '/grid/koo/home/ztang/QuantPred/wandb/sweep-lksquwjl/config-mybo8rqi.yaml'}
2021-10-13 13:30:35,920 INFO    Thread-3  :1615915 [wandb_setup.py:_flush():69] setting login settings: {}
2021-10-13 13:30:35,920 INFO    Thread-3  :1615915 [wandb_init.py:_log_setup():337] Logging user logs to /grid/koo/home/ztang/QuantPred/wandb/run-20211013_133035-mybo8rqi/logs/debug.log
2021-10-13 13:30:35,920 INFO    Thread-3  :1615915 [wandb_init.py:_log_setup():338] Logging internal logs to /grid/koo/home/ztang/QuantPred/wandb/run-20211013_133035-mybo8rqi/logs/debug-internal.log
2021-10-13 13:30:35,921 INFO    Thread-3  :1615915 [wandb_init.py:init():370] calling init triggers
2021-10-13 13:30:35,921 INFO    Thread-3  :1615915 [wandb_init.py:init():377] wandb.init called with sweep_config: {'bin_size': 128, 'data_dir': 'datasets/complete/peak_centered/i_3072_w_1/', 'l_rate': 0.001, 'loss_fn': 'pearsonr_mse', 'model_fn': 'bpnet', 'num_epochs': 100, 'window_size': 2048}
config: {}
2021-10-13 13:30:35,921 INFO    Thread-3  :1615915 [wandb_init.py:init():419] starting backend
2021-10-13 13:30:35,921 INFO    Thread-3  :1615915 [backend.py:_multiprocessing_setup():72] multiprocessing start_methods=fork,spawn,forkserver, using: spawn
2021-10-13 13:30:35,937 INFO    Thread-3  :1615915 [backend.py:ensure_launched():135] starting backend process...
2021-10-13 13:30:35,949 INFO    Thread-3  :1615915 [backend.py:ensure_launched():140] started backend process with pid: 1616388
2021-10-13 13:30:35,951 INFO    Thread-3  :1615915 [wandb_init.py:init():424] backend started and connected
2021-10-13 13:30:35,954 INFO    Thread-3  :1615915 [wandb_run.py:_config_callback():872] config_cb None None {'bin_size': 128, 'data_dir': 'datasets/complete/peak_centered/i_3072_w_1/', 'l_rate': 0.001, 'loss_fn': 'pearsonr_mse', 'model_fn': 'bpnet', 'num_epochs': 100, 'window_size': 2048}
2021-10-13 13:30:35,955 INFO    Thread-3  :1615915 [wandb_init.py:init():472] updated telemetry
2021-10-13 13:30:35,956 INFO    Thread-3  :1615915 [wandb_init.py:init():491] communicating current version
2021-10-13 13:30:36,938 INFO    Thread-3  :1615915 [wandb_init.py:init():496] got version response upgrade_message: "wandb version 0.12.4 is available!  To upgrade, please run:\n $ pip install wandb --upgrade"

2021-10-13 13:30:36,939 INFO    Thread-3  :1615915 [wandb_init.py:init():504] communicating run to backend with 30 second timeout
2021-10-13 13:30:39,712 ERROR   Thread-2  :1615915 [internal_api.py:execute():130] 429 response executing GraphQL.
2021-10-13 13:30:39,712 ERROR   Thread-2  :1615915 [internal_api.py:execute():131] {"error":"rate limit exceeded"}

2021-10-13 13:30:40,797 ERROR   Thread-2  :1615915 [internal_api.py:execute():130] 429 response executing GraphQL.
2021-10-13 13:30:40,797 ERROR   Thread-2  :1615915 [internal_api.py:execute():131] {"error":"rate limit exceeded"}

2021-10-13 13:30:43,105 ERROR   Thread-2  :1615915 [internal_api.py:execute():130] 429 response executing GraphQL.
2021-10-13 13:30:43,106 ERROR   Thread-2  :1615915 [internal_api.py:execute():131] {"error":"rate limit exceeded"}

2021-10-13 13:30:43,106 ERROR   Thread-2  :1615915 [retry.py:__call__():126] Retry attempt failed:
Traceback (most recent call last):
  File "/usr/local/lib/python3.6/dist-packages/wandb/sdk/lib/retry.py", line 102, in __call__
    result = self._call_fn(*args, **kwargs)
  File "/usr/local/lib/python3.6/dist-packages/wandb/sdk/internal/internal_api.py", line 133, in execute
    six.reraise(*sys.exc_info())
  File "/usr/local/lib/python3.6/dist-packages/six.py", line 719, in reraise
    raise value
  File "/usr/local/lib/python3.6/dist-packages/wandb/sdk/internal/internal_api.py", line 127, in execute
    return self.client.execute(*args, **kwargs)
  File "/usr/local/lib/python3.6/dist-packages/wandb/vendor/gql-0.2.0/gql/client.py", line 52, in execute
    result = self._get_result(document, *args, **kwargs)
  File "/usr/local/lib/python3.6/dist-packages/wandb/vendor/gql-0.2.0/gql/client.py", line 60, in _get_result
    return self.transport.execute(document, *args, **kwargs)
  File "/usr/local/lib/python3.6/dist-packages/wandb/vendor/gql-0.2.0/gql/transport/requests.py", line 39, in execute
    request.raise_for_status()
  File "/usr/local/lib/python3.6/dist-packages/requests/models.py", line 943, in raise_for_status
    raise HTTPError(http_error_msg, response=self)
requests.exceptions.HTTPError: 429 Client Error: Too Many Requests for url: https://api.wandb.ai/graphql
2021-10-13 13:30:51,778 ERROR   Thread-2  :1615915 [internal_api.py:execute():130] 429 response executing GraphQL.
2021-10-13 13:30:51,779 ERROR   Thread-2  :1615915 [internal_api.py:execute():131] {"error":"rate limit exceeded"}

2021-10-13 13:30:52,979 ERROR   Thread-2  :1615915 [internal_api.py:execute():130] 429 response executing GraphQL.
2021-10-13 13:30:52,979 ERROR   Thread-2  :1615915 [internal_api.py:execute():131] {"error":"rate limit exceeded"}

2021-10-13 13:30:55,355 ERROR   Thread-2  :1615915 [internal_api.py:execute():130] 429 response executing GraphQL.
2021-10-13 13:30:55,356 ERROR   Thread-2  :1615915 [internal_api.py:execute():131] {"error":"rate limit exceeded"}

2021-10-13 13:30:55,356 ERROR   Thread-2  :1615915 [retry.py:__call__():126] Retry attempt failed:
Traceback (most recent call last):
  File "/usr/local/lib/python3.6/dist-packages/wandb/sdk/lib/retry.py", line 102, in __call__
    result = self._call_fn(*args, **kwargs)
  File "/usr/local/lib/python3.6/dist-packages/wandb/sdk/internal/internal_api.py", line 133, in execute
    six.reraise(*sys.exc_info())
  File "/usr/local/lib/python3.6/dist-packages/six.py", line 719, in reraise
    raise value
  File "/usr/local/lib/python3.6/dist-packages/wandb/sdk/internal/internal_api.py", line 127, in execute
    return self.client.execute(*args, **kwargs)
  File "/usr/local/lib/python3.6/dist-packages/wandb/vendor/gql-0.2.0/gql/client.py", line 52, in execute
    result = self._get_result(document, *args, **kwargs)
  File "/usr/local/lib/python3.6/dist-packages/wandb/vendor/gql-0.2.0/gql/client.py", line 60, in _get_result
    return self.transport.execute(document, *args, **kwargs)
  File "/usr/local/lib/python3.6/dist-packages/wandb/vendor/gql-0.2.0/gql/transport/requests.py", line 39, in execute
    request.raise_for_status()
  File "/usr/local/lib/python3.6/dist-packages/requests/models.py", line 943, in raise_for_status
    raise HTTPError(http_error_msg, response=self)
requests.exceptions.HTTPError: 429 Client Error: Too Many Requests for url: https://api.wandb.ai/graphql
2021-10-13 13:30:59,609 ERROR   Thread-2  :1615915 [internal_api.py:execute():130] 429 response executing GraphQL.
2021-10-13 13:30:59,609 ERROR   Thread-2  :1615915 [internal_api.py:execute():131] {"error":"rate limit exceeded"}

2021-10-13 13:31:06,939 INFO    Thread-3  :1615915 [interface.py:_communicate_run():657] couldn't get run from backend
2021-10-13 13:31:06,940 ERROR   Thread-3  :1615915 [wandb_init.py:init():508] backend process timed out
2021-10-13 13:31:06,940 ERROR   Thread-3  :1615915 [wandb_init.py:init():517] encountered error: Error communicating with wandb process
try: wandb.init(settings=wandb.Settings(start_method='fork'))
or:  wandb.init(settings=wandb.Settings(start_method='thread'))
For more info see: https://docs.wandb.ai/library/init#init-start-error
2021-10-13 13:31:10,422 ERROR   Thread-2  :1615915 [internal_api.py:execute():130] 429 response executing GraphQL.
2021-10-13 13:31:10,422 ERROR   Thread-2  :1615915 [internal_api.py:execute():131] {"error":"rate limit exceeded"}

2021-10-13 13:31:11,674 ERROR   Thread-2  :1615915 [internal_api.py:execute():130] 429 response executing GraphQL.
2021-10-13 13:31:11,675 ERROR   Thread-2  :1615915 [internal_api.py:execute():131] {"error":"rate limit exceeded"}

2021-10-13 13:31:13,868 ERROR   Thread-2  :1615915 [internal_api.py:execute():130] 429 response executing GraphQL.
2021-10-13 13:31:13,869 ERROR   Thread-2  :1615915 [internal_api.py:execute():131] {"error":"rate limit exceeded"}

2021-10-13 13:31:13,869 ERROR   Thread-2  :1615915 [retry.py:__call__():126] Retry attempt failed:
Traceback (most recent call last):
  File "/usr/local/lib/python3.6/dist-packages/wandb/sdk/lib/retry.py", line 102, in __call__
    result = self._call_fn(*args, **kwargs)
  File "/usr/local/lib/python3.6/dist-packages/wandb/sdk/internal/internal_api.py", line 133, in execute
    six.reraise(*sys.exc_info())
  File "/usr/local/lib/python3.6/dist-packages/six.py", line 719, in reraise
    raise value
  File "/usr/local/lib/python3.6/dist-packages/wandb/sdk/internal/internal_api.py", line 127, in execute
    return self.client.execute(*args, **kwargs)
  File "/usr/local/lib/python3.6/dist-packages/wandb/vendor/gql-0.2.0/gql/client.py", line 52, in execute
    result = self._get_result(document, *args, **kwargs)
  File "/usr/local/lib/python3.6/dist-packages/wandb/vendor/gql-0.2.0/gql/client.py", line 60, in _get_result
    return self.transport.execute(document, *args, **kwargs)
  File "/usr/local/lib/python3.6/dist-packages/wandb/vendor/gql-0.2.0/gql/transport/requests.py", line 39, in execute
    request.raise_for_status()
  File "/usr/local/lib/python3.6/dist-packages/requests/models.py", line 943, in raise_for_status
    raise HTTPError(http_error_msg, response=self)
requests.exceptions.HTTPError: 429 Client Error: Too Many Requests for url: https://api.wandb.ai/graphql
2021-10-13 13:31:24,095 ERROR   Thread-2  :1615915 [internal_api.py:execute():130] 429 response executing GraphQL.
2021-10-13 13:31:24,096 ERROR   Thread-2  :1615915 [internal_api.py:execute():131] {"error":"rate limit exceeded"}

2021-10-13 13:31:25,395 ERROR   Thread-2  :1615915 [internal_api.py:execute():130] 429 response executing GraphQL.
2021-10-13 13:31:25,395 ERROR   Thread-2  :1615915 [internal_api.py:execute():131] {"error":"rate limit exceeded"}

2021-10-13 13:31:27,967 ERROR   Thread-2  :1615915 [internal_api.py:execute():130] 429 response executing GraphQL.
2021-10-13 13:31:27,968 ERROR   Thread-2  :1615915 [internal_api.py:execute():131] {"error":"rate limit exceeded"}

2021-10-13 13:31:27,968 ERROR   Thread-2  :1615915 [retry.py:__call__():126] Retry attempt failed:
Traceback (most recent call last):
  File "/usr/local/lib/python3.6/dist-packages/wandb/sdk/lib/retry.py", line 102, in __call__
    result = self._call_fn(*args, **kwargs)
  File "/usr/local/lib/python3.6/dist-packages/wandb/sdk/internal/internal_api.py", line 133, in execute
    six.reraise(*sys.exc_info())
  File "/usr/local/lib/python3.6/dist-packages/six.py", line 719, in reraise
    raise value
  File "/usr/local/lib/python3.6/dist-packages/wandb/sdk/internal/internal_api.py", line 127, in execute
    return self.client.execute(*args, **kwargs)
  File "/usr/local/lib/python3.6/dist-packages/wandb/vendor/gql-0.2.0/gql/client.py", line 52, in execute
    result = self._get_result(document, *args, **kwargs)
  File "/usr/local/lib/python3.6/dist-packages/wandb/vendor/gql-0.2.0/gql/client.py", line 60, in _get_result
    return self.transport.execute(document, *args, **kwargs)
  File "/usr/local/lib/python3.6/dist-packages/wandb/vendor/gql-0.2.0/gql/transport/requests.py", line 39, in execute
    request.raise_for_status()
  File "/usr/local/lib/python3.6/dist-packages/requests/models.py", line 943, in raise_for_status
    raise HTTPError(http_error_msg, response=self)
requests.exceptions.HTTPError: 429 Client Error: Too Many Requests for url: https://api.wandb.ai/graphql
2021-10-13 13:31:37,731 ERROR   Thread-2  :1615915 [internal_api.py:execute():130] 429 response executing GraphQL.
2021-10-13 13:31:37,732 ERROR   Thread-2  :1615915 [internal_api.py:execute():131] {"error":"rate limit exceeded"}

2021-10-13 13:31:39,021 ERROR   Thread-2  :1615915 [internal_api.py:execute():130] 429 response executing GraphQL.
2021-10-13 13:31:39,022 ERROR   Thread-2  :1615915 [internal_api.py:execute():131] {"error":"rate limit exceeded"}

2021-10-13 13:31:41,592 ERROR   Thread-2  :1615915 [internal_api.py:execute():130] 429 response executing GraphQL.
2021-10-13 13:31:41,593 ERROR   Thread-2  :1615915 [internal_api.py:execute():131] {"error":"rate limit exceeded"}

2021-10-13 13:31:41,593 ERROR   Thread-2  :1615915 [retry.py:__call__():126] Retry attempt failed:
Traceback (most recent call last):
  File "/usr/local/lib/python3.6/dist-packages/wandb/sdk/lib/retry.py", line 102, in __call__
    result = self._call_fn(*args, **kwargs)
  File "/usr/local/lib/python3.6/dist-packages/wandb/sdk/internal/internal_api.py", line 133, in execute
    six.reraise(*sys.exc_info())
  File "/usr/local/lib/python3.6/dist-packages/six.py", line 719, in reraise
    raise value
  File "/usr/local/lib/python3.6/dist-packages/wandb/sdk/internal/internal_api.py", line 127, in execute
    return self.client.execute(*args, **kwargs)
  File "/usr/local/lib/python3.6/dist-packages/wandb/vendor/gql-0.2.0/gql/client.py", line 52, in execute
    result = self._get_result(document, *args, **kwargs)
  File "/usr/local/lib/python3.6/dist-packages/wandb/vendor/gql-0.2.0/gql/client.py", line 60, in _get_result
    return self.transport.execute(document, *args, **kwargs)
  File "/usr/local/lib/python3.6/dist-packages/wandb/vendor/gql-0.2.0/gql/transport/requests.py", line 39, in execute
    request.raise_for_status()
  File "/usr/local/lib/python3.6/dist-packages/requests/models.py", line 943, in raise_for_status
    raise HTTPError(http_error_msg, response=self)
requests.exceptions.HTTPError: 429 Client Error: Too Many Requests for url: https://api.wandb.ai/graphql
2021-10-13 13:31:47,600 INFO    Thread-3  :1615915 [wandb_init.py:teardown():188] tearing down wandb.init
