2021-09-18 20:19:09,518 INFO    Thread-63 :3114041 [wandb_setup.py:_flush():69] setting env: {'root_dir': '/grid/koo/home/toneyan/profile/QuantPred', 'entity': 'toneyan', 'project': 'FINETUNE_BASENJIW1b64_POISSON_AUGM_E40', 'run_id': 'iyazh0dq', 'sweep_param_path': '/grid/koo/home/toneyan/profile/QuantPred/wandb/sweep-6c2mqhnm/config-iyazh0dq.yaml', 'sweep_id': '6c2mqhnm'}
2021-09-18 20:19:09,518 INFO    Thread-63 :3114041 [wandb_setup.py:_flush():69] setting login settings: {}
2021-09-18 20:19:09,518 INFO    Thread-63 :3114041 [wandb_init.py:_log_setup():337] Logging user logs to /grid/koo/home/toneyan/profile/QuantPred/wandb/run-20210918_201909-iyazh0dq/logs/debug.log
2021-09-18 20:19:09,518 INFO    Thread-63 :3114041 [wandb_init.py:_log_setup():338] Logging internal logs to /grid/koo/home/toneyan/profile/QuantPred/wandb/run-20210918_201909-iyazh0dq/logs/debug-internal.log
2021-09-18 20:19:09,518 INFO    Thread-63 :3114041 [wandb_init.py:init():370] calling init triggers
2021-09-18 20:19:09,518 INFO    Thread-63 :3114041 [wandb_init.py:init():377] wandb.init called with sweep_config: {'add_dropout': False, 'bin_size': 1, 'data_dir': 'datasets/complete/random_chop/i_3072_w_1/', 'filtN_1': 128, 'filtN_2': 128, 'filtN_3': 64, 'filtN_4': 128, 'filtN_5': 128, 'l_rate': 0.001, 'loss_fn': 'poisson', 'model_fn': 'basenji_w1_b64', 'num_epochs': 40, 'window_size': 2048}
config: {}
2021-09-18 20:19:09,518 INFO    Thread-63 :3114041 [wandb_init.py:init():419] starting backend
2021-09-18 20:19:09,518 INFO    Thread-63 :3114041 [backend.py:_multiprocessing_setup():72] multiprocessing start_methods=fork,spawn,forkserver, using: spawn
2021-09-18 20:19:09,521 INFO    Thread-63 :3114041 [backend.py:ensure_launched():135] starting backend process...
2021-09-18 20:19:09,543 INFO    Thread-63 :3114041 [backend.py:ensure_launched():140] started backend process with pid: 635240
2021-09-18 20:19:09,544 INFO    Thread-63 :3114041 [wandb_init.py:init():424] backend started and connected
2021-09-18 20:19:09,547 INFO    Thread-63 :3114041 [wandb_run.py:_config_callback():872] config_cb None None {'add_dropout': False, 'bin_size': 1, 'data_dir': 'datasets/complete/random_chop/i_3072_w_1/', 'filtN_1': 128, 'filtN_2': 128, 'filtN_3': 64, 'filtN_4': 128, 'filtN_5': 128, 'l_rate': 0.001, 'loss_fn': 'poisson', 'model_fn': 'basenji_w1_b64', 'num_epochs': 40, 'window_size': 2048}
2021-09-18 20:19:09,548 INFO    Thread-63 :3114041 [wandb_init.py:init():472] updated telemetry
2021-09-18 20:19:09,548 INFO    Thread-63 :3114041 [wandb_init.py:init():491] communicating current version
2021-09-18 20:19:10,122 INFO    Thread-63 :3114041 [wandb_init.py:init():496] got version response upgrade_message: "wandb version 0.12.2 is available!  To upgrade, please run:\n $ pip install wandb --upgrade"

2021-09-18 20:19:10,122 INFO    Thread-63 :3114041 [wandb_init.py:init():504] communicating run to backend with 30 second timeout
2021-09-18 20:19:12,792 ERROR   Thread-64 :3114041 [internal_api.py:execute():130] 429 response executing GraphQL.
2021-09-18 20:19:12,792 ERROR   Thread-64 :3114041 [internal_api.py:execute():131] {"error":"rate limit exceeded"}

2021-09-18 20:19:14,106 ERROR   Thread-2  :3114041 [internal_api.py:execute():130] 429 response executing GraphQL.
2021-09-18 20:19:14,106 ERROR   Thread-2  :3114041 [internal_api.py:execute():131] {"error":"rate limit exceeded"}

2021-09-18 20:19:18,041 INFO    Thread-63 :3114041 [wandb_init.py:init():529] starting run threads in backend
2021-09-18 20:19:19,174 INFO    Thread-63 :3114041 [wandb_run.py:_console_start():1623] atexit reg
2021-09-18 20:19:19,175 INFO    Thread-63 :3114041 [wandb_run.py:_redirect():1497] redirect: SettingsConsole.REDIRECT
2021-09-18 20:19:19,175 INFO    Thread-63 :3114041 [wandb_run.py:_redirect():1502] Redirecting console.
2021-09-18 20:19:19,176 ERROR   Thread-63 :3114041 [wandb_run.py:_redirect():1561] Failed to redirect.
Traceback (most recent call last):
  File "/usr/local/lib/python3.6/dist-packages/wandb/sdk/wandb_run.py", line 1554, in _redirect
    out_redir.install()
  File "/usr/local/lib/python3.6/dist-packages/wandb/sdk/lib/redirect.py", line 709, in install
    _WSCH.add_fd(self._pipe_read_fd)
  File "/usr/local/lib/python3.6/dist-packages/wandb/sdk/lib/redirect.py", line 659, in add_fd
    self._register()
  File "/usr/local/lib/python3.6/dist-packages/wandb/sdk/lib/redirect.py", line 644, in _register
    old_handler = signal.signal(signal.SIGWINCH, lambda *_: None)
  File "/usr/lib/python3.6/signal.py", line 47, in signal
    handler = _signal.signal(_enum_to_int(signalnum), _enum_to_int(handler))
ValueError: signal only works in main thread
2021-09-18 20:19:19,177 INFO    Thread-63 :3114041 [wandb_init.py:init():554] run started, returning control to user process
2021-09-18 20:19:22,791 ERROR   Thread-2  :3114041 [internal_api.py:execute():130] 429 response executing GraphQL.
2021-09-18 20:19:30,863 ERROR   Thread-2  :3114041 [internal_api.py:execute():131] {"error":"rate limit exceeded"}

2021-09-18 20:19:34,594 ERROR   Thread-2  :3114041 [internal_api.py:execute():130] 429 response executing GraphQL.
2021-09-18 20:19:34,594 ERROR   Thread-2  :3114041 [internal_api.py:execute():131] {"error":"rate limit exceeded"}

2021-09-18 20:19:35,738 ERROR   Thread-2  :3114041 [internal_api.py:execute():130] 429 response executing GraphQL.
2021-09-18 20:19:35,739 ERROR   Thread-2  :3114041 [internal_api.py:execute():131] {"error":"rate limit exceeded"}

2021-09-18 20:19:38,251 ERROR   Thread-2  :3114041 [internal_api.py:execute():130] 429 response executing GraphQL.
2021-09-18 20:19:38,251 ERROR   Thread-2  :3114041 [internal_api.py:execute():131] {"error":"rate limit exceeded"}

2021-09-18 20:19:38,251 ERROR   Thread-2  :3114041 [retry.py:__call__():126] Retry attempt failed:
Traceback (most recent call last):
  File "/usr/local/lib/python3.6/dist-packages/wandb/sdk/lib/retry.py", line 102, in __call__
    result = self._call_fn(*args, **kwargs)
  File "/usr/local/lib/python3.6/dist-packages/wandb/sdk/internal/internal_api.py", line 133, in execute
    six.reraise(*sys.exc_info())
  File "/usr/local/lib/python3.6/dist-packages/six.py", line 719, in reraise
    raise value
  File "/usr/local/lib/python3.6/dist-packages/wandb/sdk/internal/internal_api.py", line 127, in execute
    return self.client.execute(*args, **kwargs)
  File "/usr/local/lib/python3.6/dist-packages/wandb/vendor/gql-0.2.0/gql/client.py", line 52, in execute
    result = self._get_result(document, *args, **kwargs)
  File "/usr/local/lib/python3.6/dist-packages/wandb/vendor/gql-0.2.0/gql/client.py", line 60, in _get_result
    return self.transport.execute(document, *args, **kwargs)
  File "/usr/local/lib/python3.6/dist-packages/wandb/vendor/gql-0.2.0/gql/transport/requests.py", line 39, in execute
    request.raise_for_status()
  File "/usr/local/lib/python3.6/dist-packages/requests/models.py", line 943, in raise_for_status
    raise HTTPError(http_error_msg, response=self)
requests.exceptions.HTTPError: 429 Client Error: Too Many Requests for url: https://api.wandb.ai/graphql
2021-09-18 20:19:42,333 ERROR   Thread-2  :3114041 [internal_api.py:execute():130] 429 response executing GraphQL.
2021-09-18 20:19:42,333 ERROR   Thread-2  :3114041 [internal_api.py:execute():131] {"error":"rate limit exceeded"}

2021-09-18 20:19:54,023 ERROR   Thread-2  :3114041 [internal_api.py:execute():130] 429 response executing GraphQL.
2021-09-18 20:19:54,023 ERROR   Thread-2  :3114041 [internal_api.py:execute():131] {"error":"rate limit exceeded"}

2021-09-18 20:19:55,121 ERROR   Thread-2  :3114041 [internal_api.py:execute():130] 429 response executing GraphQL.
2021-09-18 20:19:55,121 ERROR   Thread-2  :3114041 [internal_api.py:execute():131] {"error":"rate limit exceeded"}

2021-09-18 20:19:57,632 ERROR   Thread-2  :3114041 [internal_api.py:execute():130] 429 response executing GraphQL.
2021-09-18 20:19:57,632 ERROR   Thread-2  :3114041 [internal_api.py:execute():131] {"error":"rate limit exceeded"}

2021-09-18 20:19:57,632 ERROR   Thread-2  :3114041 [retry.py:__call__():126] Retry attempt failed:
Traceback (most recent call last):
  File "/usr/local/lib/python3.6/dist-packages/wandb/sdk/lib/retry.py", line 102, in __call__
    result = self._call_fn(*args, **kwargs)
  File "/usr/local/lib/python3.6/dist-packages/wandb/sdk/internal/internal_api.py", line 133, in execute
    six.reraise(*sys.exc_info())
  File "/usr/local/lib/python3.6/dist-packages/six.py", line 719, in reraise
    raise value
  File "/usr/local/lib/python3.6/dist-packages/wandb/sdk/internal/internal_api.py", line 127, in execute
    return self.client.execute(*args, **kwargs)
  File "/usr/local/lib/python3.6/dist-packages/wandb/vendor/gql-0.2.0/gql/client.py", line 52, in execute
    result = self._get_result(document, *args, **kwargs)
  File "/usr/local/lib/python3.6/dist-packages/wandb/vendor/gql-0.2.0/gql/client.py", line 60, in _get_result
    return self.transport.execute(document, *args, **kwargs)
  File "/usr/local/lib/python3.6/dist-packages/wandb/vendor/gql-0.2.0/gql/transport/requests.py", line 39, in execute
    request.raise_for_status()
  File "/usr/local/lib/python3.6/dist-packages/requests/models.py", line 943, in raise_for_status
    raise HTTPError(http_error_msg, response=self)
requests.exceptions.HTTPError: 429 Client Error: Too Many Requests for url: https://api.wandb.ai/graphql
2021-09-18 20:20:04,439 INFO    Thread-63 :3114041 [wandb_run.py:finish():1293] finishing run toneyan/FINETUNE_BASENJIW1b64_POISSON_AUGM_E40/iyazh0dq
