2021-11-01 11:19:17,546 INFO    Thread-3  :3179663 [wandb_setup.py:_flush():69] setting env: {'root_dir': '/grid/koo/home/toneyan/profile/QuantPred', 'sweep_id': 'doc2czfg', 'entity': 'toneyan', 'project': 'NEW_MODELS_BASERES', 'run_id': 'v4iozxug', 'sweep_param_path': '/grid/koo/home/toneyan/profile/QuantPred/wandb/sweep-doc2czfg/config-v4iozxug.yaml'}
2021-11-01 11:19:17,546 INFO    Thread-3  :3179663 [wandb_setup.py:_flush():69] setting login settings: {}
2021-11-01 11:19:17,546 INFO    Thread-3  :3179663 [wandb_init.py:_log_setup():337] Logging user logs to /grid/koo/home/toneyan/profile/QuantPred/wandb/run-20211101_111917-v4iozxug/logs/debug.log
2021-11-01 11:19:17,546 INFO    Thread-3  :3179663 [wandb_init.py:_log_setup():338] Logging internal logs to /grid/koo/home/toneyan/profile/QuantPred/wandb/run-20211101_111917-v4iozxug/logs/debug-internal.log
2021-11-01 11:19:17,547 INFO    Thread-3  :3179663 [wandb_init.py:init():370] calling init triggers
2021-11-01 11:19:17,547 INFO    Thread-3  :3179663 [wandb_init.py:init():377] wandb.init called with sweep_config: {'activation': 'relu', 'bin_size': 1, 'crop': 'r_crop', 'data_dir': 'datasets/complete/random_chop/i_3072_w_1', 'es_patience': 10, 'l_rate': 0.001, 'loss_fn': 'poisson', 'lr_decay': 0.2, 'lr_patience': 3, 'model_fn': 'residual_profile_all_base', 'num_epochs': 100, 'rev_comp': True, 'window_size': 2048}
config: {}
2021-11-01 11:19:17,547 INFO    Thread-3  :3179663 [wandb_init.py:init():419] starting backend
2021-11-01 11:19:17,547 INFO    Thread-3  :3179663 [backend.py:_multiprocessing_setup():72] multiprocessing start_methods=fork,spawn,forkserver, using: spawn
2021-11-01 11:19:17,556 INFO    Thread-3  :3179663 [backend.py:ensure_launched():135] starting backend process...
2021-11-01 11:19:17,561 INFO    Thread-3  :3179663 [backend.py:ensure_launched():140] started backend process with pid: 3179824
2021-11-01 11:19:17,562 INFO    Thread-3  :3179663 [wandb_init.py:init():424] backend started and connected
2021-11-01 11:19:17,564 INFO    Thread-3  :3179663 [wandb_run.py:_config_callback():872] config_cb None None {'activation': 'relu', 'bin_size': 1, 'crop': 'r_crop', 'data_dir': 'datasets/complete/random_chop/i_3072_w_1', 'es_patience': 10, 'l_rate': 0.001, 'loss_fn': 'poisson', 'lr_decay': 0.2, 'lr_patience': 3, 'model_fn': 'residual_profile_all_base', 'num_epochs': 100, 'rev_comp': True, 'window_size': 2048}
2021-11-01 11:19:17,564 INFO    Thread-3  :3179663 [wandb_init.py:init():472] updated telemetry
2021-11-01 11:19:17,565 INFO    Thread-3  :3179663 [wandb_init.py:init():491] communicating current version
2021-11-01 11:19:18,111 INFO    Thread-3  :3179663 [wandb_init.py:init():496] got version response upgrade_message: "wandb version 0.12.6 is available!  To upgrade, please run:\n $ pip install wandb --upgrade"

2021-11-01 11:19:18,112 INFO    Thread-3  :3179663 [wandb_init.py:init():504] communicating run to backend with 30 second timeout
2021-11-01 11:19:18,220 INFO    Thread-3  :3179663 [wandb_init.py:init():529] starting run threads in backend
2021-11-01 11:19:19,279 INFO    Thread-3  :3179663 [wandb_run.py:_console_start():1623] atexit reg
2021-11-01 11:19:19,280 INFO    Thread-3  :3179663 [wandb_run.py:_redirect():1497] redirect: SettingsConsole.REDIRECT
2021-11-01 11:19:19,281 INFO    Thread-3  :3179663 [wandb_run.py:_redirect():1502] Redirecting console.
2021-11-01 11:19:19,285 ERROR   Thread-3  :3179663 [wandb_run.py:_redirect():1561] Failed to redirect.
Traceback (most recent call last):
  File "/usr/local/lib/python3.6/dist-packages/wandb/sdk/wandb_run.py", line 1554, in _redirect
    out_redir.install()
  File "/usr/local/lib/python3.6/dist-packages/wandb/sdk/lib/redirect.py", line 709, in install
    _WSCH.add_fd(self._pipe_read_fd)
  File "/usr/local/lib/python3.6/dist-packages/wandb/sdk/lib/redirect.py", line 659, in add_fd
    self._register()
  File "/usr/local/lib/python3.6/dist-packages/wandb/sdk/lib/redirect.py", line 644, in _register
    old_handler = signal.signal(signal.SIGWINCH, lambda *_: None)
  File "/usr/lib/python3.6/signal.py", line 47, in signal
    handler = _signal.signal(_enum_to_int(signalnum), _enum_to_int(handler))
ValueError: signal only works in main thread
2021-11-01 11:19:19,288 INFO    Thread-3  :3179663 [wandb_init.py:init():554] run started, returning control to user process
2021-11-01 16:00:52,143 ERROR   Thread-2  :3179663 [internal_api.py:execute():130] 500 response executing GraphQL.
2021-11-01 16:00:52,157 ERROR   Thread-2  :3179663 [internal_api.py:execute():131] {"errors":[{"message":"Error 1040: Too many connections","path":["agentHeartbeat"]}],"data":{"agentHeartbeat":null}}
2021-11-01 16:01:03,169 ERROR   Thread-2  :3179663 [internal_api.py:execute():130] 500 response executing GraphQL.
2021-11-01 16:01:03,170 ERROR   Thread-2  :3179663 [internal_api.py:execute():131] {"error":"Error 1040: Too many connections"}

2021-11-01 16:01:05,554 ERROR   Thread-2  :3179663 [internal_api.py:execute():130] 500 response executing GraphQL.
2021-11-01 16:01:05,554 ERROR   Thread-2  :3179663 [internal_api.py:execute():131] {"error":"Error 1040: Too many connections"}

2021-11-01 16:01:05,554 ERROR   Thread-2  :3179663 [retry.py:__call__():126] Retry attempt failed:
Traceback (most recent call last):
  File "/usr/local/lib/python3.6/dist-packages/wandb/sdk/lib/retry.py", line 102, in __call__
    result = self._call_fn(*args, **kwargs)
  File "/usr/local/lib/python3.6/dist-packages/wandb/sdk/internal/internal_api.py", line 133, in execute
    six.reraise(*sys.exc_info())
  File "/usr/local/lib/python3.6/dist-packages/six.py", line 719, in reraise
    raise value
  File "/usr/local/lib/python3.6/dist-packages/wandb/sdk/internal/internal_api.py", line 127, in execute
    return self.client.execute(*args, **kwargs)
  File "/usr/local/lib/python3.6/dist-packages/wandb/vendor/gql-0.2.0/gql/client.py", line 52, in execute
    result = self._get_result(document, *args, **kwargs)
  File "/usr/local/lib/python3.6/dist-packages/wandb/vendor/gql-0.2.0/gql/client.py", line 60, in _get_result
    return self.transport.execute(document, *args, **kwargs)
  File "/usr/local/lib/python3.6/dist-packages/wandb/vendor/gql-0.2.0/gql/transport/requests.py", line 39, in execute
    request.raise_for_status()
  File "/usr/local/lib/python3.6/dist-packages/requests/models.py", line 943, in raise_for_status
    raise HTTPError(http_error_msg, response=self)
requests.exceptions.HTTPError: 500 Server Error: Internal Server Error for url: https://api.wandb.ai/graphql
2021-11-01 16:01:11,088 ERROR   Thread-2  :3179663 [internal_api.py:execute():130] 500 response executing GraphQL.
2021-11-01 16:01:11,089 ERROR   Thread-2  :3179663 [internal_api.py:execute():131] {"errors":[{"message":"Error 1040: Too many connections","path":["agentHeartbeat"]}],"data":{"agentHeartbeat":null}}
2021-11-01 16:01:20,556 ERROR   Thread-2  :3179663 [internal_api.py:execute():130] 500 response executing GraphQL.
2021-11-01 16:01:20,558 ERROR   Thread-2  :3179663 [internal_api.py:execute():131] {"error":"Error 1040: Too many connections"}

2021-11-01 16:01:38,497 ERROR   Thread-2  :3179663 [internal_api.py:execute():130] 500 response executing GraphQL.
2021-11-01 16:01:38,497 ERROR   Thread-2  :3179663 [internal_api.py:execute():131] {"errors":[{"message":"Error 1040: Too many connections","path":["agentHeartbeat"]}],"data":{"agentHeartbeat":null}}
2021-11-04 03:56:09,669 INFO    Thread-3  :3179663 [wandb_run.py:finish():1293] finishing run toneyan/NEW_MODELS_BASERES/v4iozxug
